<?xml version="1.0" ?>
<robot xmlns:xacro="http://wiki.ros.org/xacro">
  <xacro:macro name="lego_large_motor" params="name parent *origin">
    <link name="${name}_link">
      <visual>
        <geometry>
          <mesh filename="package://lego_spike_description/meshes/SpikePrimeLargeMotor.stl" scale="0.0004 0.0004 0.0004"/>
        </geometry>
        <material name="lego_white" />
        <origin xyz="0 0.005 0" rpy="1.5707963267948966 0 1.5707963267948966" />
      </visual>
      <!-- TODO: collision -->
    </link>
    <joint name="${name}_joint" type="fixed">
      <parent link="${parent}" />
      <child link="${name}_link" />
      <xacro:insert_block name="origin" />
    </joint>

    <link name="${name}_wheel_link" />
    <joint name="${name}_wheel_joint" type="continuous">
      <parent link="${name}_link" />
      <child link="${name}_wheel_link" />
      <origin xyz="0.02 0 0.03" rpy="0 0 0" />
      <axis xyz="0 0 1" />
    </joint>
  </xacro:macro>
</robot>
